Workbook

Sheet Sheet1
A1: Id | B1: Name | C1: Group | D1: Active | E1: Rating | F1: PlayerType
A2: 1 | B2: A. Veld | C2: 2 | D2: 1 | E2: 1454 | F2: Youth | G2: ="("&A2&",'"&B2&"','"&C2&"',true,"&E2&",'"&F2&"')," -> (1,'A. Veld','2',true,1454,'Youth'), | I2: =IFERROR(VLOOKUP(B2,N:O,2,FALSE),0) -> 1 | J2: =VLOOKUP(B2,N:P,3,FALSE) -> 2
A3: 2 | B3: B. Ahlers | C3: 1 | D3: 1 | E3: 2092 | F3: Senior | G3: ="("&A3&",'"&B3&"','"&C3&"',true,"&E3&",'"&F3&"')," -> (2,'B. Ahlers','1',true,2092,'Senior'), | I3: =IFERROR(VLOOKUP(B3,N:O,2,FALSE),0) -> 1 | J3: =VLOOKUP(B3,N:P,3,FALSE) -> 1 | N3: H. Boerkamp | O3: 0 | P3: 1
A4: 3 | B4: B. Albertus | C4: 1 | D4: 1 | E4: 2071 | F4: Senior | G4: ="("&A4&",'"&B4&"','"&C4&"',true,"&E4&",'"&F4&"')," -> (3,'B. Albertus','1',true,2071,'Senior'), | I4: =IFERROR(VLOOKUP(B4,N:O,2,FALSE),0) -> 1 | J4: =VLOOKUP(B4,N:P,3,FALSE) -> 1 | N4: B. Bannink | O4: 1 | P4: 1
A5: 4 | B5: C. Remie | C5: 2 | D5: 1 | F5: Senior | G5: ="("&A5&",'"&B5&"','"&C5&"',true,"&E5&",'"&F5&"')," -> (4,'C. Remie','2',true,,'Senior'), | I5: =IFERROR(VLOOKUP(B5,N:O,2,FALSE),0) -> 1 | J5: =VLOOKUP(B5,N:P,3,FALSE) -> 2 | N5: H. Noordhoek | O5: 1 | P5: 1
A6: 5 | B6: C. Schoon | C6: 2 | D6: 1 | E6: 1603 | F6: Senior | G6: ="("&A6&",'"&B6&"','"&C6&"',true,"&E6&",'"&F6&"')," -> (5,'C. Schoon','2',true,1603,'Senior'), | I6: =IFERROR(VLOOKUP(B6,N:O,2,FALSE),0) -> 0 | J6: =VLOOKUP(B6,N:P,3,FALSE) -> 2 | N6: S. de Swart | O6: 1 | P6: 1
A7: 6 | B7: C. Veld | C7: 2 | D7: 1 | F7: Senior | G7: ="("&A7&",'"&B7&"','"&C7&"',true,"&E7&",'"&F7&"')," -> (6,'C. Veld','2',true,,'Senior'), | I7: =IFERROR(VLOOKUP(B7,N:O,2,FALSE),0) -> 1 | J7: =VLOOKUP(B7,N:P,3,FALSE) -> 2 | N7: B. Albertus | O7: 1 | P7: 1
A8: 7 | B8: D. Bhoelan | C8: 2 | D8: 1 | F8: Senior | G8: ="("&A8&",'"&B8&"','"&C8&"',true,"&E8&",'"&F8&"')," -> (7,'D. Bhoelan','2',true,,'Senior'), | I8: =IFERROR(VLOOKUP(B8,N:O,2,FALSE),0) -> 0 | J8: =VLOOKUP(B8,N:P,3,FALSE) -> #N/A | N8: M. Nepveu | O8: 1 | P8: 1
A9: 8 | B9: D. Brinkman | C9: 2 | D9: 1 | E9: 1700 | F9: Senior | G9: ="("&A9&",'"&B9&"','"&C9&"',true,"&E9&",'"&F9&"')," -> (8,'D. Brinkman','2',true,1700,'Senior'), | I9: =IFERROR(VLOOKUP(B9,N:O,2,FALSE),0) -> 1 | J9: =VLOOKUP(B9,N:P,3,FALSE) -> 2 | N9: B. Ahlers | O9: 1 | P9: 1
A10: 9 | B10: D. Kanbier | C10: 1 | D10: 1 | E10: 1778 | F10: Senior | G10: ="("&A10&",'"&B10&"','"&C10&"',true,"&E10&",'"&F10&"')," -> (9,'D. Kanbier','1',true,1778,'Senior'), | I10: =IFERROR(VLOOKUP(B10,N:O,2,FALSE),0) -> 1 | J10: =VLOOKUP(B10,N:P,3,FALSE) -> 1 | N10: D. Kanbier | O10: 1 | P10: 1
A11: 10 | B11: D. Ramadan | C11: 2 | D11: 1 | E11: 1819 | F11: Senior | G11: ="("&A11&",'"&B11&"','"&C11&"',true,"&E11&",'"&F11&"')," -> (10,'D. Ramadan','2',true,1819,'Senior'), | I11: =IFERROR(VLOOKUP(B11,N:O,2,FALSE),0) -> 1 | J11: =VLOOKUP(B11,N:P,3,FALSE) -> 2 | N11: S. Kooiman | O11: 1 | P11: 1
A12: 11 | B12: D. Strikwerda | C12: 2 | D12: 1 | E12: 1200 | F12: Senior | G12: ="("&A12&",'"&B12&"','"&C12&"',true,"&E12&",'"&F12&"')," -> (11,'D. Strikwerda','2',true,1200,'Senior'), | I12: =IFERROR(VLOOKUP(B12,N:O,2,FALSE),0) -> 1 | J12: =VLOOKUP(B12,N:P,3,FALSE) -> 2 | N12: H. Minnema | O12: 1 | P12: 1
A13: 12 | B13: D. van Nies | C13: 2 | D13: 1 | E13: 1734 | F13: Senior | G13: ="("&A13&",'"&B13&"','"&C13&"',true,"&E13&",'"&F13&"')," -> (12,'D. van Nies','2',true,1734,'Senior'), | I13: =IFERROR(VLOOKUP(B13,N:O,2,FALSE),0) -> 1 | J13: =VLOOKUP(B13,N:P,3,FALSE) -> 2 | N13: H. Ouwens | O13: 1 | P13: 1
A14: 13 | B14: E. Guijt | C14: 2 | D14: 1 | E14: 1906 | F14: Senior | G14: ="("&A14&",'"&B14&"','"&C14&"',true,"&E14&",'"&F14&"')," -> (13,'E. Guijt','2',true,1906,'Senior'), | I14: =IFERROR(VLOOKUP(B14,N:O,2,FALSE),0) -> 1 | J14: =VLOOKUP(B14,N:P,3,FALSE) -> 2 | N14: J. Veldhuizen | O14: 1 | P14: 1
A15: 14 | B15: F. Martens | C15: 2 | D15: 1 | E15: 1715 | F15: Senior | G15: ="("&A15&",'"&B15&"','"&C15&"',true,"&E15&",'"&F15&"')," -> (14,'F. Martens','2',true,1715,'Senior'), | I15: =IFERROR(VLOOKUP(B15,N:O,2,FALSE),0) -> 1 | J15: =VLOOKUP(B15,N:P,3,FALSE) -> 2 | N15: P. van der Werve | O15: 1 | P15: 1
A16: 15 | B16: G. Eggink | C16: 2 | D16: 1 | E16: 1886 | F16: Senior | G16: ="("&A16&",'"&B16&"','"&C16&"',true,"&E16&",'"&F16&"')," -> (15,'G. Eggink','2',true,1886,'Senior'), | I16: =IFERROR(VLOOKUP(B16,N:O,2,FALSE),0) -> 1 | J16: =VLOOKUP(B16,N:P,3,FALSE) -> 2 | N16: J. Baas | O16: 1 | P16: 1
A17: 16 | B17: H. Minnema | C17: 1 | D17: 1 | E17: 1815 | F17: Senior | G17: ="("&A17&",'"&B17&"','"&C17&"',true,"&E17&",'"&F17&"')," -> (16,'H. Minnema','1',true,1815,'Senior'), | I17: =IFERROR(VLOOKUP(B17,N:O,2,FALSE),0) -> 1 | J17: =VLOOKUP(B17,N:P,3,FALSE) -> 1 | N17: J. Koster | O17: 1 | P17: 1
A18: 17 | B18: H. Noordhoek | C18: 1 | D18: 1 | E18: 2001 | F18: Senior | G18: ="("&A18&",'"&B18&"','"&C18&"',true,"&E18&",'"&F18&"')," -> (17,'H. Noordhoek','1',true,2001,'Senior'), | I18: =IFERROR(VLOOKUP(B18,N:O,2,FALSE),0) -> 1 | J18: =VLOOKUP(B18,N:P,3,FALSE) -> 1
A19: 18 | B19: H. Ouwens | C19: 1 | D19: 1 | E19: 1956 | F19: Senior | G19: ="("&A19&",'"&B19&"','"&C19&"',true,"&E19&",'"&F19&"')," -> (18,'H. Ouwens','1',true,1956,'Senior'), | I19: =IFERROR(VLOOKUP(B19,N:O,2,FALSE),0) -> 1 | J19: =VLOOKUP(B19,N:P,3,FALSE) -> 1 | N19: G. Eggink | O19: 1 | P19: 2
A20: 19 | B20: J. Baas | C20: 1 | D20: 1 | E20: 1976 | F20: Senior | G20: ="("&A20&",'"&B20&"','"&C20&"',true,"&E20&",'"&F20&"')," -> (19,'J. Baas','1',true,1976,'Senior'), | I20: =IFERROR(VLOOKUP(B20,N:O,2,FALSE),0) -> 1 | J20: =VLOOKUP(B20,N:P,3,FALSE) -> 1 | N20: K. van der Heijden | O20: 1 | P20: 2
A21: 20 | B21: J. Blankespoor | C21: 1 | D21: 1 | E21: 1922 | F21: Senior | G21: ="("&A21&",'"&B21&"','"&C21&"',true,"&E21&",'"&F21&"')," -> (20,'J. Blankespoor','1',true,1922,'Senior'), | I21: =IFERROR(VLOOKUP(B21,N:O,2,FALSE),0) -> 0 | J21: =VLOOKUP(B21,N:P,3,FALSE) -> 1 | N21: C. Remie | O21: 1 | P21: 2
A22: 21 | B22: J. de Roo | C22: 2 | D22: 1 | E22: 1615 | F22: Senior | G22: ="("&A22&",'"&B22&"','"&C22&"',true,"&E22&",'"&F22&"')," -> (21,'J. de Roo','2',true,1615,'Senior'), | I22: =IFERROR(VLOOKUP(B22,N:O,2,FALSE),0) -> 1 | J22: =VLOOKUP(B22,N:P,3,FALSE) -> 2 | N22: D. Ramadan | O22: 1 | P22: 2
A23: 22 | B23: J. Koster | C23: 1 | D23: 1 | E23: 1928 | F23: Senior | G23: ="("&A23&",'"&B23&"','"&C23&"',true,"&E23&",'"&F23&"')," -> (22,'J. Koster','1',true,1928,'Senior'), | I23: =IFERROR(VLOOKUP(B23,N:O,2,FALSE),0) -> 1 | J23: =VLOOKUP(B23,N:P,3,FALSE) -> 1 | N23: S. de Vries | O23: 1 | P23: 2
A24: 23 | B24: J. Lipka | C24: 2 | D24: 1 | E24: 1656 | F24: Senior | G24: ="("&A24&",'"&B24&"','"&C24&"',true,"&E24&",'"&F24&"')," -> (23,'J. Lipka','2',true,1656,'Senior'), | I24: =IFERROR(VLOOKUP(B24,N:O,2,FALSE),0) -> 0 | J24: =VLOOKUP(B24,N:P,3,FALSE) -> 2 | N24: Tom van der Helm | O24: 1 | P24: 2
A25: 24 | B25: J. Mostert | C25: 1 | D25: 1 | E25: 1894 | F25: Senior | G25: ="("&A25&",'"&B25&"','"&C25&"',true,"&E25&",'"&F25&"')," -> (24,'J. Mostert','1',true,1894,'Senior'), | I25: =IFERROR(VLOOKUP(B25,N:O,2,FALSE),0) -> 0 | J25: =VLOOKUP(B25,N:P,3,FALSE) -> 1 | N25: R. de Vries | O25: 1 | P25: 2
A26: 25 | B26: J. Sibbing | C26: 1 | D26: 1 | E26: 1906 | F26: Senior | G26: ="("&A26&",'"&B26&"','"&C26&"',true,"&E26&",'"&F26&"')," -> (25,'J. Sibbing','1',true,1906,'Senior'), | I26: =IFERROR(VLOOKUP(B26,N:O,2,FALSE),0) -> 0 | J26: =VLOOKUP(B26,N:P,3,FALSE) -> 1 | N26: T. vd Nieuwendijk | O26: 1 | P26: 2
A27: 26 | B27: J. Tan | C27: 1 | D27: 1 | E27: 1858 | F27: Senior | G27: ="("&A27&",'"&B27&"','"&C27&"',true,"&E27&",'"&F27&"')," -> (26,'J. Tan','1',true,1858,'Senior'), | I27: =IFERROR(VLOOKUP(B27,N:O,2,FALSE),0) -> 0 | J27: =VLOOKUP(B27,N:P,3,FALSE) -> 1 | N27: E. Guijt | O27: 1 | P27: 2
A28: 27 | B28: J. van den Berg | C28: 1 | D28: 1 | E28: 1848 | F28: Senior | G28: ="("&A28&",'"&B28&"','"&C28&"',true,"&E28&",'"&F28&"')," -> (27,'J. van den Berg','1',true,1848,'Senior'), | I28: =IFERROR(VLOOKUP(B28,N:O,2,FALSE),0) -> 0 | J28: =VLOOKUP(B28,N:P,3,FALSE) -> 1 | N28: D. Strikwerda | O28: 1 | P28: 2
A29: 28 | B29: J. Veldhuizen | C29: 1 | D29: 1 | E29: 1767 | F29: Senior | G29: ="("&A29&",'"&B29&"','"&C29&"',true,"&E29&",'"&F29&"')," -> (28,'J. Veldhuizen','1',true,1767,'Senior'), | I29: =IFERROR(VLOOKUP(B29,N:O,2,FALSE),0) -> 1 | J29: =VLOOKUP(B29,N:P,3,FALSE) -> 1 | N29: A. Veld | O29: 1 | P29: 2
A30: 29 | B30: J.W. Duijzer | C30: 1 | D30: 1 | E30: 2124 | F30: Senior | G30: ="("&A30&",'"&B30&"','"&C30&"',true,"&E30&",'"&F30&"')," -> (29,'J.W. Duijzer','1',true,2124,'Senior'), | I30: =IFERROR(VLOOKUP(B30,N:O,2,FALSE),0) -> 0 | J30: =VLOOKUP(B30,N:P,3,FALSE) -> 1 | N30: C. Veld | O30: 1 | P30: 2
A31: 30 | B31: K. Breed | C31: 2 | D31: 1 | F31: Senior | G31: ="("&A31&",'"&B31&"','"&C31&"',true,"&E31&",'"&F31&"')," -> (30,'K. Breed','2',true,,'Senior'), | I31: =IFERROR(VLOOKUP(B31,N:O,2,FALSE),0) -> 0 | J31: =VLOOKUP(B31,N:P,3,FALSE) -> #N/A | N31: O. van den Bout | O31: 1 | P31: 2
A32: 31 | B32: M. Engelsman | C32: 2 | D32: 1 | F32: Senior | G32: ="("&A32&",'"&B32&"','"&C32&"',true,"&E32&",'"&F32&"')," -> (31,'M. Engelsman','2',true,,'Senior'), | I32: =IFERROR(VLOOKUP(B32,N:O,2,FALSE),0) -> 0 | J32: =VLOOKUP(B32,N:P,3,FALSE) -> #N/A | N32: J. de Roo | O32: 1 | P32: 2
A33: 32 | B33: M. Hettfleisch | C33: 1 | D33: 1 | E33: 1891 | F33: Senior | G33: ="("&A33&",'"&B33&"','"&C33&"',true,"&E33&",'"&F33&"')," -> (32,'M. Hettfleisch','1',true,1891,'Senior'), | I33: =IFERROR(VLOOKUP(B33,N:O,2,FALSE),0) -> 0 | J33: =VLOOKUP(B33,N:P,3,FALSE) -> 1 | N33: F. Martens | O33: 1 | P33: 2
A34: 33 | B34: M. Nepveu | C34: 1 | D34: 1 | E34: 1968 | F34: Senior | G34: ="("&A34&",'"&B34&"','"&C34&"',true,"&E34&",'"&F34&"')," -> (33,'M. Nepveu','1',true,1968,'Senior'), | I34: =IFERROR(VLOOKUP(B34,N:O,2,FALSE),0) -> 1 | J34: =VLOOKUP(B34,N:P,3,FALSE) -> 1 | N34: D. Brinkman | O34: 1 | P34: 2
A35: 34 | B35: M. Wichhart | C35: 1 | D35: 1 | E35: 1936 | F35: Senior | G35: ="("&A35&",'"&B35&"','"&C35&"',true,"&E35&",'"&F35&"')," -> (34,'M. Wichhart','1',true,1936,'Senior'), | I35: =IFERROR(VLOOKUP(B35,N:O,2,FALSE),0) -> 0 | J35: =VLOOKUP(B35,N:P,3,FALSE) -> 1 | N35: D. van Nies | O35: 1 | P35: 2
A36: 35 | B36: N. Peerdeman | C36: 1 | D36: 1 | E36: 1944 | F36: Senior | G36: ="("&A36&",'"&B36&"','"&C36&"',true,"&E36&",'"&F36&"')," -> (35,'N. Peerdeman','1',true,1944,'Senior'), | I36: =IFERROR(VLOOKUP(B36,N:O,2,FALSE),0) -> 0 | J36: =VLOOKUP(B36,N:P,3,FALSE) -> 1 | N36: Tim van der Helm | O36: 1 | P36: 2
A37: 36 | B37: O. van den Bout | C37: 2 | D37: 1 | E37: 1749 | F37: Youth | G37: ="("&A37&",'"&B37&"','"&C37&"',true,"&E37&",'"&F37&"')," -> (36,'O. van den Bout','2',true,1749,'Youth'), | I37: =IFERROR(VLOOKUP(B37,N:O,2,FALSE),0) -> 1 | J37: =VLOOKUP(B37,N:P,3,FALSE) -> 2
A38: 37 | B38: P. Hijma | C38: 2 | D38: 1 | E38: 1650 | F38: Senior | G38: ="("&A38&",'"&B38&"','"&C38&"',true,"&E38&",'"&F38&"')," -> (37,'P. Hijma','2',true,1650,'Senior'), | I38: =IFERROR(VLOOKUP(B38,N:O,2,FALSE),0) -> 0 | J38: =VLOOKUP(B38,N:P,3,FALSE) -> 2 | N38: J. Blankespoor | O38: 0 | P38: 1
A39: 38 | B39: P. van der Werve | C39: 1 | D39: 1 | E39: 2062 | F39: Senior | G39: ="("&A39&",'"&B39&"','"&C39&"',true,"&E39&",'"&F39&"')," -> (38,'P. van der Werve','1',true,2062,'Senior'), | I39: =IFERROR(VLOOKUP(B39,N:O,2,FALSE),0) -> 1 | J39: =VLOOKUP(B39,N:P,3,FALSE) -> 1 | N39: M. Wichhart | O39: 0 | P39: 1
A40: 39 | B40: R. de Vries | C40: 2 | D40: 1 | E40: 1639 | F40: Senior | G40: ="("&A40&",'"&B40&"','"&C40&"',true,"&E40&",'"&F40&"')," -> (39,'R. de Vries','2',true,1639,'Senior'), | I40: =IFERROR(VLOOKUP(B40,N:O,2,FALSE),0) -> 1 | J40: =VLOOKUP(B40,N:P,3,FALSE) -> 2 | N40: J.W. Duijzer | O40: 0 | P40: 1
...

Sheet Sheet6
A1: J.Baas:
A2: Rem | B2: 9
A3: Rem | B3: 9
A4: Afwezig | B4: 12 | C4: Extern?
A5: Rem | B5: 9
A6: Afwezig | B6: 6
A7: Winst | B7: 18
A8: Extern | B8: 12
A9: Rem | B9: 9
A10: Afwezig | B10: 6
A11: Verlies | B11: 0

Sheet Sheet2
A1: Round | B1: Period | C1: Number | D1: Year | E1: Date | F1: Played
A2: 1 | B2: 1 | C2: 1 | D2: 2025 | E2: 45859 | F2: 1 | G2: ="('"&A2&"','"&B2&"','"&C2&"','"&D2&"','"&DAY(E2)&"-"&MONTH(E2)&"-"&YEAR(E2)&"','"&F2&"')," -> ('1','1','1','2025','21-7-2025','1'),
A3: 2 | B3: 1 | C3: 1 | D3: 2025 | E3: 45859 | F3: 1 | G3: ="('"&A3&"','"&B3&"','"&C3&"','"&D3&"','"&DAY(E3)&"-"&MONTH(E3)&"-"&YEAR(E3)&"','"&F3&"')," -> ('2','1','1','2025','21-7-2025','1'),
A4: 3 | B4: 1 | C4: 1 | D4: 2025 | E4: 45866 | F4: 0 | G4: ="('"&A4&"','"&B4&"','"&C4&"','"&D4&"','"&DAY(E4)&"-"&MONTH(E4)&"-"&YEAR(E4)&"','"&F4&"')," -> ('3','1','1','2025','28-7-2025','0'),
A5: 4 | B5: 1 | C5: 1 | D5: 2025 | E5: 45866 | F5: 0 | G5: ="('"&A5&"','"&B5&"','"&C5&"','"&D5&"','"&DAY(E5)&"-"&MONTH(E5)&"-"&YEAR(E5)&"','"&F5&"')," -> ('4','1','1','2025','28-7-2025','0'),
A6: 5 | B6: 1 | C6: 1 | D6: 2025 | E6: 45873 | F6: 0 | G6: ="('"&A6&"','"&B6&"','"&C6&"','"&D6&"','"&DAY(E6)&"-"&MONTH(E6)&"-"&YEAR(E6)&"','"&F6&"')," -> ('5','1','1','2025','4-8-2025','0'),
A7: 6 | B7: 1 | C7: 1 | D7: 2025 | E7: 45873 | F7: 0 | G7: ="('"&A7&"','"&B7&"','"&C7&"','"&D7&"','"&DAY(E7)&"-"&MONTH(E7)&"-"&YEAR(E7)&"','"&F7&"')," -> ('6','1','1','2025','4-8-2025','0'),
A8: 7 | B8: 1 | C8: 1 | D8: 2025 | E8: 45880 | F8: 0 | G8: ="('"&A8&"','"&B8&"','"&C8&"','"&D8&"','"&DAY(E8)&"-"&MONTH(E8)&"-"&YEAR(E8)&"','"&F8&"')," -> ('7','1','1','2025','11-8-2025','0'),
A9: 8 | B9: 1 | C9: 1 | D9: 2025 | E9: 45880 | F9: 0 | G9: ="('"&A9&"','"&B9&"','"&C9&"','"&D9&"','"&DAY(E9)&"-"&MONTH(E9)&"-"&YEAR(E9)&"','"&F9&"')," -> ('8','1','1','2025','11-8-2025','0'),
A10: 9 | B10: 1 | C10: 1 | D10: 2025 | E10: 45887 | F10: 0 | G10: ="('"&A10&"','"&B10&"','"&C10&"','"&D10&"','"&DAY(E10)&"-"&MONTH(E10)&"-"&YEAR(E10)&"','"&F10&"')," -> ('9','1','1','2025','18-8-2025','0'),
A11: 10 | B11: 1 | C11: 1 | D11: 2025 | E11: 45887 | F11: 0 | G11: ="('"&A11&"','"&B11&"','"&C11&"','"&D11&"','"&DAY(E11)&"-"&MONTH(E11)&"-"&YEAR(E11)&"','"&F11&"')," -> ('10','1','1','2025','18-8-2025','0'),
A12: 11 | B12: 1 | C12: 1 | D12: 2025 | E12: 45894 | F12: 0 | G12: ="('"&A12&"','"&B12&"','"&C12&"','"&D12&"','"&DAY(E12)&"-"&MONTH(E12)&"-"&YEAR(E12)&"','"&F12&"')," -> ('11','1','1','2025','25-8-2025','0'),
A13: 12 | B13: 1 | C13: 1 | D13: 2025 | E13: 45894 | F13: 0 | G13: ="('"&A13&"','"&B13&"','"&C13&"','"&D13&"','"&DAY(E13)&"-"&MONTH(E13)&"-"&YEAR(E13)&"','"&F13&"')," -> ('12','1','1','2025','25-8-2025','0'),

Sheet Sheet3
A1: Round Id | B1: PlayerId | C1: Present | D1: Reason absent Result Id
A2: 1 | B2: 1 | C2: =VLOOKUP(B2,Sheet1!A:I,9,FALSE) -> 1 | E2: ="('"&A2&"','"&B2&"','"&C2&"',NULL)," -> ('1','1','1',NULL),
A3: =IF(B3=1,A2+1,A2) -> 1 | B3: 2 | C3: =VLOOKUP(B3,Sheet1!A:I,9,FALSE) -> 1 | E3: ="('"&A3&"','"&B3&"','"&C3&"',NULL)," -> ('1','2','1',NULL),
A4: =IF(B4=1,A3+1,A3) -> 1 | B4: 3 | C4: =VLOOKUP(B4,Sheet1!A:I,9,FALSE) -> 1 | E4: ="('"&A4&"','"&B4&"','"&C4&"',NULL)," -> ('1','3','1',NULL),
A5: =IF(B5=1,A4+1,A4) -> 1 | B5: 4 | C5: =VLOOKUP(B5,Sheet1!A:I,9,FALSE) -> 1 | E5: ="('"&A5&"','"&B5&"','"&C5&"',NULL)," -> ('1','4','1',NULL),
A6: =IF(B6=1,A5+1,A5) -> 1 | B6: 5 | C6: =VLOOKUP(B6,Sheet1!A:I,9,FALSE) -> 0 | E6: ="('"&A6&"','"&B6&"','"&C6&"',NULL)," -> ('1','5','0',NULL),
A7: =IF(B7=1,A6+1,A6) -> 1 | B7: 6 | C7: =VLOOKUP(B7,Sheet1!A:I,9,FALSE) -> 1 | E7: ="('"&A7&"','"&B7&"','"&C7&"',NULL)," -> ('1','6','1',NULL),
A8: =IF(B8=1,A7+1,A7) -> 1 | B8: 7 | C8: =VLOOKUP(B8,Sheet1!A:I,9,FALSE) -> 0 | E8: ="('"&A8&"','"&B8&"','"&C8&"',NULL)," -> ('1','7','0',NULL),
A9: =IF(B9=1,A8+1,A8) -> 1 | B9: 8 | C9: =VLOOKUP(B9,Sheet1!A:I,9,FALSE) -> 1 | E9: ="('"&A9&"','"&B9&"','"&C9&"',NULL)," -> ('1','8','1',NULL),
A10: =IF(B10=1,A9+1,A9) -> 1 | B10: 9 | C10: =VLOOKUP(B10,Sheet1!A:I,9,FALSE) -> 1 | E10: ="('"&A10&"','"&B10&"','"&C10&"',NULL)," -> ('1','9','1',NULL),
A11: =IF(B11=1,A10+1,A10) -> 1 | B11: 10 | C11: =VLOOKUP(B11,Sheet1!A:I,9,FALSE) -> 1 | E11: ="('"&A11&"','"&B11&"','"&C11&"',NULL)," -> ('1','10','1',NULL),
A12: =IF(B12=1,A11+1,A11) -> 1 | B12: 11 | C12: =VLOOKUP(B12,Sheet1!A:I,9,FALSE) -> 1 | E12: ="('"&A12&"','"&B12&"','"&C12&"',NULL)," -> ('1','11','1',NULL),
A13: =IF(B13=1,A12+1,A12) -> 1 | B13: 12 | C13: =VLOOKUP(B13,Sheet1!A:I,9,FALSE) -> 1 | E13: ="('"&A13&"','"&B13&"','"&C13&"',NULL)," -> ('1','12','1',NULL),
A14: =IF(B14=1,A13+1,A13) -> 1 | B14: 13 | C14: =VLOOKUP(B14,Sheet1!A:I,9,FALSE) -> 1 | E14: ="('"&A14&"','"&B14&"','"&C14&"',NULL)," -> ('1','13','1',NULL),
... A50: =IF(B50=1,A49+1,A49) -> 1 | B50: 49 | C50: =VLOOKUP(B50,Sheet1!A:I,9,FALSE) -> 1 | E50: ="('"&A50&"','"&B50&"','"&C50&"',NULL)," -> ('1','49','1',NULL),
A51: =IF(B51=1,A50+1,A50) -> 2 | B51: 1 | C51: 1 | E51: ="('"&A51&"','"&B51&"','"&C51&"',NULL)," -> ('2','1','1',NULL),
A52: =IF(B52=1,A51+1,A51) -> 2 | B52: 2 | C52: 1 | E52: ="('"&A52&"','"&B52&"','"&C52&"',NULL)," -> ('2','2','1',NULL),
A53: =IF(B53=1,A52+1,A52) -> 2 | B53: 3 | C53: 1 | E53: ="('"&A53&"','"&B53&"','"&C53&"',NULL)," -> ('2','3','1',NULL),
A54: =IF(B54=1,A53+1,A53) -> 2 | B54: 4 | C54: 1 | E54: ="('"&A54&"','"&B54&"','"&C54&"',NULL)," -> ('2','4','1',NULL),
A55: =IF(B55=1,A54+1,A54) -> 2 | B55: 5 | C55: 1 | E55: ="('"&A55&"','"&B55&"','"&C55&"',NULL)," -> ('2','5','1',NULL),
A56: =IF(B56=1,A55+1,A55) -> 2 | B56: 6 | C56: 1 | E56: ="('"&A56&"','"&B56&"','"&C56&"',NULL)," -> ('2','6','1',NULL),
A57: =IF(B57=1,A56+1,A56) -> 2 | B57: 7 | C57: 1 | E57: ="('"&A57&"','"&B57&"','"&C57&"',NULL)," -> ('2','7','1',NULL),
A58: =IF(B58=1,A57+1,A57) -> 2 | B58: 8 | C58: 1 | E58: ="('"&A58&"','"&B58&"','"&C58&"',NULL)," -> ('2','8','1',NULL),
A59: =IF(B59=1,A58+1,A58) -> 2 | B59: 9 | C59: 1 | E59: ="('"&A59&"','"&B59&"','"&C59&"',NULL)," -> ('2','9','1',NULL),
A60: =IF(B60=1,A59+1,A59) -> 2 | B60: 10 | C60: 1 | E60: ="('"&A60&"','"&B60&"','"&C60&"',NULL)," -> ('2','10','1',NULL),
A61: =IF(B61=1,A60+1,A60) -> 2 | B61: 11 | C61: 1 | E61: ="('"&A61&"','"&B61&"','"&C61&"',NULL)," -> ('2','11','1',NULL),
A62: =IF(B62=1,A61+1,A61) -> 2 | B62: 12 | C62: 1 | E62: ="('"&A62&"','"&B62&"','"&C62&"',NULL)," -> ('2','12','1',NULL),
... A589: =IF(B589=1,A588+1,A588) -> 12 | B589: 49 | C589: 1 | E589: ="('"&A589&"','"&B589&"','"&C589&"',NULL)," -> ('12','49','1',NULL),
A590: 1 | B590: 50 | C590: =VLOOKUP(B590,Sheet1!A:I,9,FALSE) -> 0 | E590: ="('"&A590&"','"&B590&"','"&C590&"',NULL)," -> ('1','50','0',NULL),
A591: 1 | B591: 51 | C591: =VLOOKUP(B591,Sheet1!A:I,9,FALSE) -> 1 | E591: ="('"&A591&"','"&B591&"','"&C591&"',NULL)," -> ('1','51','1',NULL),
A592: 1 | B592: 52 | C592: =VLOOKUP(B592,Sheet1!A:I,9,FALSE) -> 1 | E592: ="('"&A592&"','"&B592&"','"&C592&"',NULL)," -> ('1','52','1',NULL),
A593: 1 | B593: 53 | C593: =VLOOKUP(B593,Sheet1!A:I,9,FALSE) -> 0 | E593: ="('"&A593&"','"&B593&"','"&C593&"',NULL)," -> ('1','53','0',NULL),
A594: 1 | B594: 54 | C594: =VLOOKUP(B594,Sheet1!A:I,9,FALSE) -> 0 | E594: ="('"&A594&"','"&B594&"','"&C594&"',NULL)," -> ('1','54','0',NULL),
A595: =A590+1 -> 2 | B595: 50 | C595: 1 | E595: ="('"&A595&"','"&B595&"','"&C595&"',NULL)," -> ('2','50','1',NULL),
A596: =A591+1 -> 2 | B596: 51 | C596: 1 | E596: ="('"&A596&"','"&B596&"','"&C596&"',NULL)," -> ('2','51','1',NULL),
A597: =A592+1 -> 2 | B597: 52 | C597: 1 | E597: ="('"&A597&"','"&B597&"','"&C597&"',NULL)," -> ('2','52','1',NULL),
A598: =A593+1 -> 2 | B598: 53 | C598: 1 | E598: ="('"&A598&"','"&B598&"','"&C598&"',NULL)," -> ('2','53','1',NULL),
A599: =A594+1 -> 2 | B599: 54 | C599: 1 | E599: ="('"&A599&"','"&B599&"','"&C599&"',NULL)," -> ('2','54','1',NULL),
A600: =A595+1 -> 3 | B600: 50 | C600: 1 | E600: ="('"&A600&"','"&B600&"','"&C600&"',NULL)," -> ('3','50','1',NULL),
A601: =A596+1 -> 3 | B601: 51 | C601: 1 | E601: ="('"&A601&"','"&B601&"','"&C601&"',NULL)," -> ('3','51','1',NULL),
...

Sheet Sheet4
A1: Settings
A2: Id | B2: Name | C2: Value | D2: Description
A3: 1 | B3: CompType | C3: percentage | D3: Specifies the type of competition, current options: percentage, swiss | E3: ="('"&A3&"','"&B3&"','"&C3&"','"&D3&"')," -> ('1','CompType','percentage','Specifies the type of competition, current options: percentage, swiss'),
A4: 2 | B4: Year | C4: 2025 | D4: Year the competition started in | E4: ="('"&A4&"','"&B4&"','"&C4&"','"&D4&"')," -> ('2','Year','2025','Year the competition started in'),
A5: 3 | B5: NumberOfPeriodRounds | C5: 12 | E5: ="('"&A5&"','"&B5&"','"&C5&"','"&"NULL"&"')," -> ('3','NumberOfPeriodRounds','12','NULL'),
A6: 4 | B6: NumberOfNonCompete | C6: 12 | E6: ="('"&A6&"','"&B6&"','"&C6&"','"&"NULL"&"')," -> ('4','NumberOfNonCompete','12','NULL'),
A7: 5 | B7: RoundsForBye1 | C7: 0 | E7: ="('"&A7&"','"&B7&"','"&C7&"','"&"NULL"&"')," -> ('5','RoundsForBye1','0','NULL'),
A8: 6 | B8: PointsForBye1 | C8: 0 | E8: ="('"&A8&"','"&B8&"','"&C8&"','"&"NULL"&"')," -> ('6','PointsForBye1','0','NULL'),
A9: 7 | B9: RoundsForBye2 | C9: 0 | E9: ="('"&A9&"','"&B9&"','"&C9&"','"&"NULL"&"')," -> ('7','RoundsForBye2','0','NULL'),
A10: 8 | B10: PointsForBye2 | C10: 0 | E10: ="('"&A10&"','"&B10&"','"&C10&"','"&"NULL"&"')," -> ('8','PointsForBye2','0','NULL'),
A11: 9 | B11: RoundsForBye3 | C11: 0 | E11: ="('"&A11&"','"&B11&"','"&C11&"','"&"NULL"&"')," -> ('9','RoundsForBye3','0','NULL'),
A12: 10 | B12: PontsForBye3 | C12: 0 | E12: ="('"&A12&"','"&B12&"','"&C12&"','"&"NULL"&"')," -> ('10','PontsForBye3','0','NULL'),
A13: 11 | B13: MinimumPresent | C13: 6 | E13: ="('"&A13&"','"&B13&"','"&C13&"','"&"NULL"&"')," -> ('11','MinimumPresent','6','NULL'),

Sheet Results
A1: Id | B1: Name | C1: GroupNumber | D1: Results Type | E1: Points | K1: PlayerId | L1: GroupNumber | M1: SUM(Points)
A2: 1 | B2: Win | C2: 1 | D2: 1 | E2: 18 | F2: ="('"&A2&"','"&B2&"','"&C2&"','"&D2&"','"&E2&"')," -> ('1','Win','1','1','18'), | K2: 18 | L2: 1 | M2: 36 | N2: =VLOOKUP(K2,Sheet1!A:B,2,FALSE) -> H. Ouwens
A3: 2 | B3: Draw | C3: 1 | D3: 2 | E3: 9 | F3: ="('"&A3&"','"&B3&"','"&C3&"','"&D3&"','"&E3&"')," -> ('2','Draw','1','2','9'), | K3: 17 | L3: 1 | M3: 27 | N3: =VLOOKUP(K3,Sheet1!A:B,2,FALSE) -> H. Noordhoek
A4: 3 | B4: Loss | C4: 1 | D4: 3 | E4: 0 | F4: ="('"&A4&"','"&B4&"','"&C4&"','"&D4&"','"&E4&"')," -> ('3','Loss','1','3','0'), | K4: 3 | L4: 1 | M4: 27 | N4: =VLOOKUP(K4,Sheet1!A:B,2,FALSE) -> B. Albertus
A5: 4 | B5: Absent | C5: 1 | D5: 4 | E5: 6 | F5: ="('"&A5&"','"&B5&"','"&C5&"','"&D5&"','"&E5&"')," -> ('4','Absent','1','4','6'), | K5: 33 | L5: 1 | M5: 27 | N5: =VLOOKUP(K5,Sheet1!A:B,2,FALSE) -> M. Nepveu
A6: 5 | B6: Absent more than allowed | C6: 1 | D6: 4 | E6: 3 | F6: ="('"&A6&"','"&B6&"','"&C6&"','"&D6&"','"&E6&"')," -> ('5','Absent more than allowed','1','4','3'), | K6: 38 | L6: 1 | M6: 27 | N6: =VLOOKUP(K6,Sheet1!A:B,2,FALSE) -> P. van der Werve
A7: 6 | B7: Extern | C7: 1 | D7: 4 | E7: 12 | F7: ="('"&A7&"','"&B7&"','"&C7&"','"&D7&"','"&E7&"')," -> ('6','Extern','1','4','12'), | K7: 51 | L7: 1 | M7: 27 | N7: =VLOOKUP(K7,Sheet1!A:B,2,FALSE) -> B. Bannink
A8: 7 | B8: Extern more than allowed | C8: 1 | D8: 4 | E8: 6 | F8: ="('"&A8&"','"&B8&"','"&C8&"','"&D8&"','"&E8&"')," -> ('7','Extern more than allowed','1','4','6'), | K8: 15 | L8: 2 | M8: 24 | N8: =VLOOKUP(K8,Sheet1!A:B,2,FALSE) -> G. Eggink
A9: 8 | B9: Wedstrijd leider | C9: 1 | D9: 4 | E9: 12 | F9: ="('"&A9&"','"&B9&"','"&C9&"','"&D9&"','"&E9&"')," -> ('8','Wedstrijd leider','1','4','12'), | K9: 10 | L9: 2 | M9: 18 | N9: =VLOOKUP(K9,Sheet1!A:B,2,FALSE) -> D. Ramadan
A10: 9 | B10: Bye1 | C10: 1 | D10: 4 | E10: 0 | F10: ="('"&A10&"','"&B10&"','"&C10&"','"&D10&"','"&E10&"')," -> ('9','Bye1','1','4','0'), | K10: 16 | L10: 1 | M10: 12 | N10: =VLOOKUP(K10,Sheet1!A:B,2,FALSE) -> H. Minnema
A11: 10 | B11: Bye2 | C11: 1 | D11: 4 | E11: 0 | F11: ="('"&A11&"','"&B11&"','"&C11&"','"&D11&"','"&E11&"')," -> ('10','Bye2','1','4','0'), | K11: 19 | L11: 1 | M11: 18 | N11: =VLOOKUP(K11,Sheet1!A:B,2,FALSE) -> J. Baas
A12: 11 | B12: Bye3 | C12: 1 | D12: 4 | E12: 0 | F12: ="('"&A12&"','"&B12&"','"&C12&"','"&D12&"','"&E12&"')," -> ('11','Bye3','1','4','0'), | K12: 22 | L12: 1 | M12: 18 | N12: =VLOOKUP(K12,Sheet1!A:B,2,FALSE) -> J. Koster
A13: =A12+1 -> 12 | B13: Win | C13: 1 | D13: 1 | E13: 12 | F13: ="('"&A13&"','"&B13&"','"&C13&"','"&D13&"','"&E13&"')," -> ('12','Win','1','1','12'), | K13: 43 | L13: 1 | M13: 18 | N13: =VLOOKUP(K13,Sheet1!A:B,2,FALSE) -> S. de Swart
A14: =A13+1 -> 13 | B14: Draw | C14: 1 | D14: 2 | E14: 6 | F14: ="('"&A14&"','"&B14&"','"&C14&"','"&D14&"','"&E14&"')," -> ('13','Draw','1','2','6'), | K14: 47 | L14: 2 | M14: 18 | N14: =VLOOKUP(K14,Sheet1!A:B,2,FALSE) -> T. vd Nieuwendijk
A15: =A14+1 -> 14 | B15: Loss | C15: 1 | D15: 3 | E15: 0 | F15: ="('"&A15&"','"&B15&"','"&C15&"','"&D15&"','"&E15&"')," -> ('14','Loss','1','3','0'), | K15: 48 | L15: 2 | M15: 18 | N15: =VLOOKUP(K15,Sheet1!A:B,2,FALSE) -> Tim van der Helm
A16: =A15+1 -> 15 | B16: Absent | C16: 1 | D16: 4 | E16: 4 | F16: ="('"&A16&"','"&B16&"','"&C16&"','"&D16&"','"&E16&"')," -> ('15','Absent','1','4','4'), | K16: 8 | L16: 2 | M16: 18 | N16: =VLOOKUP(K16,Sheet1!A:B,2,FALSE) -> D. Brinkman
A17: =A16+1 -> 16 | B17: Absent more than allowed | C17: 1 | D17: 4 | E17: 3 | F17: ="('"&A17&"','"&B17&"','"&C17&"','"&D17&"','"&E17&"')," -> ('16','Absent more than allowed','1','4','3'), | K17: 53 | L17: 2 | M17: 16 | N17: =VLOOKUP(K17,Sheet1!A:B,2,FALSE) -> F. van Bolhuis
A18: =A17+1 -> 17 | B18: Extern | C18: 1 | D18: 4 | E18: 8 | F18: ="('"&A18&"','"&B18&"','"&C18&"','"&D18&"','"&E18&"')," -> ('17','Extern','1','4','8'), | K18: 7 | L18: 2 | M18: 16 | N18: =VLOOKUP(K18,Sheet1!A:B,2,FALSE) -> D. Bhoelan
A19: =A18+1 -> 18 | B19: Extern more than allowed | C19: 1 | D19: 4 | E19: 4 | F19: ="('"&A19&"','"&B19&"','"&C19&"','"&D19&"','"&E19&"')," -> ('18','Extern more than allowed','1','4','4'), | K19: 32 | L19: 1 | M19: 15 | N19: =VLOOKUP(K19,Sheet1!A:B,2,FALSE) -> M. Hettfleisch
A20: =A19+1 -> 19 | B20: Wedstrijd leider | C20: 1 | D20: 4 | E20: 8 | F20: ="('"&A20&"','"&B20&"','"&C20&"','"&D20&"','"&E20&"')," -> ('19','Wedstrijd leider','1','4','8'), | K20: 34 | L20: 1 | M20: 15 | N20: =VLOOKUP(K20,Sheet1!A:B,2,FALSE) -> M. Wichhart
A21: =A20+1 -> 20 | B21: Bye1 | C21: 1 | D21: 4 | E21: 0 | F21: ="('"&A21&"','"&B21&"','"&C21&"','"&D21&"','"&E21&"')," -> ('20','Bye1','1','4','0'), | K21: 42 | L21: 1 | M21: 15 | N21: =VLOOKUP(K21,Sheet1!A:B,2,FALSE) -> R. Minnema
A22: =A21+1 -> 21 | B22: Bye2 | C22: 1 | D22: 4 | E22: 0 | F22: ="('"&A22&"','"&B22&"','"&C22&"','"&D22&"','"&E22&"')," -> ('21','Bye2','1','4','0'), | K22: 46 | L22: 1 | M22: 15 | N22: =VLOOKUP(K22,Sheet1!A:B,2,FALSE) -> T. Morcus
A23: =A22+1 -> 22 | B23: Bye3 | C23: 1 | D23: 4 | E23: 0 | F23: ="('"&A23&"','"&B23&"','"&C23&"','"&D23&"','"&E23&"')," -> ('22','Bye3','1','4','0'), | K23: 1 | L23: 2 | M23: 12 | N23: =VLOOKUP(K23,Sheet1!A:B,2,FALSE) -> A. Veld
A24: 23 | B24: Uneven | C24: 1 | D24: 5 | E24: 12 | F24: ="('"&A24&"','"&B24&"','"&C24&"','"&D24&"','"&E24&"')," -> ('23','Uneven','1','5','12'), | K24: 12 | L24: 2 | M24: 12 | N24: =VLOOKUP(K24,Sheet1!A:B,2,FALSE) -> D. van Nies
A25: 24 | B25: Uneven | C25: 2 | D25: 5 | E25: 9 | F25: ="('"&A25&"','"&B25&"','"&C25&"','"&D25&"','"&E25&"')," -> ('24','Uneven','2','5','9'), | K25: 20 | L25: 1 | M25: 12 | N25: =VLOOKUP(K25,Sheet1!A:B,2,FALSE) -> J. Blankespoor
K26: 21 | L26: 2 | M26: 12 | N26: =VLOOKUP(K26,Sheet1!A:B,2,FALSE) -> J. de Roo
K27: 25 | L27: 1 | M27: 12 | N27: =VLOOKUP(K27,Sheet1!A:B,2,FALSE) -> J. Sibbing
K28: 26 | L28: 1 | M28: 12 | N28: =VLOOKUP(K28,Sheet1!A:B,2,FALSE) -> J. Tan
K29: 27 | L29: 1 | M29: 12 | N29: =VLOOKUP(K29,Sheet1!A:B,2,FALSE) -> J. van den Berg
K30: 29 | L30: 1 | M30: 12 | N30: =VLOOKUP(K30,Sheet1!A:B,2,FALSE) -> J.W. Duijzer
K31: 35 | L31: 1 | M31: 12 | N31: =VLOOKUP(K31,Sheet1!A:B,2,FALSE) -> N. Peerdeman
K32: 4 | L32: 2 | M32: 12 | N32: =VLOOKUP(K32,Sheet1!A:B,2,FALSE) -> C. Remie
K33: 44 | L33: 2 | M33: 12 | N33: =VLOOKUP(K33,Sheet1!A:B,2,FALSE) -> S. de Vries
K34: 49 | L34: 2 | M34: 12 | N34: =VLOOKUP(K34,Sheet1!A:B,2,FALSE) -> Tom van der Helm
K35: 50 | L35: 1 | M35: 12 | N35: =VLOOKUP(K35,Sheet1!A:B,2,FALSE) -> H. Boerkamp
K36: 52 | L36: 2 | M36: 12 | N36: =VLOOKUP(K36,Sheet1!A:B,2,FALSE) -> K. van der Heijden
K37: 24 | L37: 1 | M37: 12 | N37: =VLOOKUP(K37,Sheet1!A:B,2,FALSE) -> J. Mostert
... K56: 999 | L56: 1 | M56: 0 | N56: =VLOOKUP(K56,Sheet1!A:B,2,FALSE) -> #N/A
